{
 "cells": [
  {
   "cell_type": "raw",
   "metadata": {
    "deletable": true,
    "editable": true
   },
   "source": [
    "1. Create a classification problem with 3 classes, 15 features and 5000 rows\n",
    "2. Take the last 1000 rows to be the test set\n",
    "3. Run Gaussian naive bayes on this problem and report test accuracy\n",
    "4. Calculate class prior probabilities for each class in training data (first 4k rows)\n",
    "5. Calculate the probability of the samples for each class in the test set\n",
    "\n",
    "References:\n",
    "    http://scikit-learn.org/stable/modules/generated/sklearn.datasets.make_classification.html\n",
    "    http://scikit-learn.org/stable/modules/generated/sklearn.naive_bayes.GaussianNB.html#sklearn.naive_bayes.GaussianNB"
   ]
  },
  {
   "cell_type": "code",
   "execution_count": 2,
   "metadata": {
    "collapsed": false
   },
   "outputs": [
    {
     "name": "stderr",
     "output_type": "stream",
     "text": [
      "ERROR:root:Internal Python error in the inspect module.\n",
      "Below is the traceback from this internal error.\n",
      "\n"
     ]
    },
    {
     "name": "stdout",
     "output_type": "stream",
     "text": [
      "Traceback (most recent call last):\n",
      "  File \"/Users/xiasong/anaconda2/envs/py36/lib/python3.6/site-packages/IPython/core/interactiveshell.py\", line 2881, in run_code\n",
      "    exec(code_obj, self.user_global_ns, self.user_ns)\n",
      "  File \"<ipython-input-2-f98a21ea157c>\", line 2, in <module>\n",
      "    x,y = make_calssification(n_samples=5000, n_features=15, n_classes=3, n_clusters_per_class=1)\n",
      "NameError: name 'make_calssification' is not defined\n",
      "\n",
      "During handling of the above exception, another exception occurred:\n",
      "\n",
      "Traceback (most recent call last):\n",
      "  File \"/Users/xiasong/anaconda2/envs/py36/lib/python3.6/site-packages/IPython/core/interactiveshell.py\", line 1821, in showtraceback\n",
      "    stb = value._render_traceback_()\n",
      "AttributeError: 'NameError' object has no attribute '_render_traceback_'\n",
      "\n",
      "During handling of the above exception, another exception occurred:\n",
      "\n",
      "Traceback (most recent call last):\n",
      "  File \"/Users/xiasong/anaconda2/envs/py36/lib/python3.6/site-packages/IPython/core/ultratb.py\", line 1132, in get_records\n",
      "    return _fixed_getinnerframes(etb, number_of_lines_of_context, tb_offset)\n",
      "  File \"/Users/xiasong/anaconda2/envs/py36/lib/python3.6/site-packages/IPython/core/ultratb.py\", line 313, in wrapped\n",
      "    return f(*args, **kwargs)\n",
      "  File \"/Users/xiasong/anaconda2/envs/py36/lib/python3.6/site-packages/IPython/core/ultratb.py\", line 358, in _fixed_getinnerframes\n",
      "    records = fix_frame_records_filenames(inspect.getinnerframes(etb, context))\n",
      "  File \"/Users/xiasong/anaconda2/envs/py36/lib/python3.6/inspect.py\", line 1453, in getinnerframes\n",
      "    frameinfo = (tb.tb_frame,) + getframeinfo(tb, context)\n",
      "  File \"/Users/xiasong/anaconda2/envs/py36/lib/python3.6/inspect.py\", line 1411, in getframeinfo\n",
      "    filename = getsourcefile(frame) or getfile(frame)\n",
      "  File \"/Users/xiasong/anaconda2/envs/py36/lib/python3.6/inspect.py\", line 666, in getsourcefile\n",
      "    if getattr(getmodule(object, filename), '__loader__', None) is not None:\n",
      "  File \"/Users/xiasong/anaconda2/envs/py36/lib/python3.6/inspect.py\", line 695, in getmodule\n",
      "    file = getabsfile(object, _filename)\n",
      "  File \"/Users/xiasong/anaconda2/envs/py36/lib/python3.6/inspect.py\", line 679, in getabsfile\n",
      "    return os.path.normcase(os.path.abspath(_filename))\n",
      "  File \"/Users/xiasong/anaconda2/envs/py36/lib/python3.6/posixpath.py\", line 374, in abspath\n",
      "    cwd = os.getcwd()\n",
      "FileNotFoundError: [Errno 2] No such file or directory\n"
     ]
    },
    {
     "ename": "NameError",
     "evalue": "name 'make_calssification' is not defined",
     "output_type": "error",
     "traceback": [
      "\u001b[0;31m---------------------------------------------------------------------------\u001b[0m"
     ]
    }
   ],
   "source": [
    "from sklearn.datasets import make_classification\n",
    "x,y = make_calssification(n_samples=5000, n_features=15, n_classes=3, n_clusters_per_class=1)"
   ]
  },
  {
   "cell_type": "code",
   "execution_count": null,
   "metadata": {
    "collapsed": true
   },
   "outputs": [],
   "source": []
  }
 ],
 "metadata": {
  "kernelspec": {
   "display_name": "Python [conda env:py36]",
   "language": "python",
   "name": "conda-env-py36-py"
  },
  "language_info": {
   "codemirror_mode": {
    "name": "ipython",
    "version": 3
   },
   "file_extension": ".py",
   "mimetype": "text/x-python",
   "name": "python",
   "nbconvert_exporter": "python",
   "pygments_lexer": "ipython3",
   "version": "3.6.1"
  }
 },
 "nbformat": 4,
 "nbformat_minor": 2
}
